<?xml version="1.0"?>
<robot name="my_robot" xmlns:xacro="http://www.ros.org/wiki/xacro">

  <!-- ===================== Properties ===================== -->
  <xacro:property name="base_radius"  value="0.15"/>
  <xacro:property name="base_height"  value="0.15"/>
  <xacro:property name="base_mass"    value="5.0"/>

  <xacro:property name="wheel_radius" value="0.05"/>
  <xacro:property name="wheel_width"  value="0.04"/>
  <xacro:property name="wheel_mass"   value="0.5"/>
  <xacro:property name="wheel_separation" value="0.28"/>

  <xacro:property name="caster_radius" value="0.025"/>
  <xacro:property name="caster_mass"   value="0.1"/>

  <xacro:property name="lidar_radius"  value="0.035"/>
  <xacro:property name="lidar_height"  value="0.04"/>
  <xacro:property name="lidar_mass"    value="0.1"/>

  <!-- ===================== Inertia Macros ===================== -->
  <xacro:macro name="inertial_cylinder" params="mass radius length *origin">
    <inertial>
      <xacro:insert_block name="origin"/>
      <mass value="${mass}"/>
      <inertia
        ixx="${(1/12) * mass * (3 * radius * radius + length * length)}"
        ixy="0.0" ixz="0.0"
        iyy="${(1/12) * mass * (3 * radius * radius + length * length)}"
        iyz="0.0"
        izz="${(1/2) * mass * radius * radius}"/>
    </inertial>
  </xacro:macro>

  <xacro:macro name="inertial_sphere" params="mass radius *origin">
    <inertial>
      <xacro:insert_block name="origin"/>
      <mass value="${mass}"/>
      <inertia
        ixx="${(2/5) * mass * radius * radius}"
        ixy="0.0" ixz="0.0"
        iyy="${(2/5) * mass * radius * radius}"
        iyz="0.0"
        izz="${(2/5) * mass * radius * radius}"/>
    </inertial>
  </xacro:macro>

  <!-- ===================== Base Link ===================== -->
  <link name="base_footprint"/>

  <joint name="base_footprint_joint" type="fixed">
    <parent link="base_footprint"/>
    <child link="base_link"/>
    <origin xyz="0 0 ${wheel_radius}" rpy="0 0 0"/>
  </joint>

  <link name="base_link">
    <visual>
      <geometry>
        <cylinder radius="${base_radius}" length="${base_height}"/>
      </geometry>
      <material name="blue">
        <color rgba="0.0 0.5 1.0 1.0"/>
      </material>
    </visual>
    <collision>
      <geometry>
        <cylinder radius="${base_radius}" length="${base_height}"/>
      </geometry>
    </collision>
    <xacro:inertial_cylinder mass="${base_mass}" radius="${base_radius}" length="${base_height}">
      <origin xyz="0 0 0" rpy="0 0 0"/>
    </xacro:inertial_cylinder>
  </link>

  <!-- ===================== Wheel Macro ===================== -->
  <xacro:macro name="wheel" params="name y_reflect">
    <link name="${name}_wheel_link">
      <visual>
        <geometry>
          <cylinder radius="${wheel_radius}" length="${wheel_width}"/>
        </geometry>
        <material name="dark_grey">
          <color rgba="0.2 0.2 0.2 1.0"/>
        </material>
      </visual>
      <collision>
        <geometry>
          <cylinder radius="${wheel_radius}" length="${wheel_width}"/>
        </geometry>
      </collision>
      <xacro:inertial_cylinder mass="${wheel_mass}" radius="${wheel_radius}" length="${wheel_width}">
        <origin xyz="0 0 0" rpy="0 0 0"/>
      </xacro:inertial_cylinder>
    </link>

    <joint name="${name}_wheel_joint" type="continuous">
      <parent link="base_link"/>
      <child link="${name}_wheel_link"/>
      <origin xyz="0 ${y_reflect * wheel_separation / 2} ${-base_height / 2 + wheel_radius}" rpy="${-pi/2} 0 0"/>
      <axis xyz="0 0 1"/>
      <dynamics damping="0.01" friction="0.1"/>
    </joint>
  </xacro:macro>

  <xacro:wheel name="left"  y_reflect="1"/>
  <xacro:wheel name="right" y_reflect="-1"/>

  <!-- ===================== Caster Wheels ===================== -->
  <xacro:macro name="caster" params="name x_offset">
    <link name="${name}_caster_link">
      <visual>
        <geometry>
          <sphere radius="${caster_radius}"/>
        </geometry>
        <material name="grey">
          <color rgba="0.5 0.5 0.5 1.0"/>
        </material>
      </visual>
      <collision>
        <geometry>
          <sphere radius="${caster_radius}"/>
        </geometry>
      </collision>
      <xacro:inertial_sphere mass="${caster_mass}" radius="${caster_radius}">
        <origin xyz="0 0 0" rpy="0 0 0"/>
      </xacro:inertial_sphere>
    </link>

    <joint name="${name}_caster_joint" type="fixed">
      <parent link="base_link"/>
      <child link="${name}_caster_link"/>
      <origin xyz="${x_offset} 0 ${-base_height / 2}" rpy="0 0 0"/>
    </joint>
  </xacro:macro>

  <xacro:caster name="front" x_offset="${base_radius - caster_radius}"/>
  <xacro:caster name="rear"  x_offset="${-(base_radius - caster_radius)}"/>

  <!-- ===================== Lidar ===================== -->
  <link name="lidar_link">
    <visual>
      <geometry>
        <cylinder radius="${lidar_radius}" length="${lidar_height}"/>
      </geometry>
      <material name="black">
        <color rgba="0.1 0.1 0.1 1.0"/>
      </material>
    </visual>
    <collision>
      <geometry>
        <cylinder radius="${lidar_radius}" length="${lidar_height}"/>
      </geometry>
    </collision>
    <xacro:inertial_cylinder mass="${lidar_mass}" radius="${lidar_radius}" length="${lidar_height}">
      <origin xyz="0 0 0" rpy="0 0 0"/>
    </xacro:inertial_cylinder>
  </link>

  <joint name="lidar_joint" type="fixed">
    <parent link="base_link"/>
    <child link="lidar_link"/>
    <origin xyz="0 0 ${base_height / 2 + lidar_height / 2}" rpy="0 0 0"/>
  </joint>

  <!-- ===================== IMU ===================== -->
  <link name="imu_link">
    <visual>
      <geometry>
        <box size="0.02 0.02 0.01"/>
      </geometry>
      <material name="orange">
        <color rgba="1.0 0.5 0.0 1.0"/>
      </material>
    </visual>
    <inertial>
      <mass value="0.01"/>
      <inertia ixx="1e-6" ixy="0" ixz="0" iyy="1e-6" iyz="0" izz="1e-6"/>
    </inertial>
  </link>

  <joint name="imu_joint" type="fixed">
    <parent link="base_link"/>
    <child link="imu_link"/>
    <origin xyz="0 0 0" rpy="0 0 0"/>
  </joint>

  <!-- ===================== Gazebo Plugins ===================== -->
  <xacro:include filename="$(find my_robot_description)/urdf/my_robot_gazebo.xacro"/>

</robot>
